## try...catch

用一句话描述 JS 异常是否能被 try catch 到：

能捕捉到的异常，必须是线程执行已经进入 try catch 但 try catch 未执行完的时候抛出来的。

try catch 执行之前，之中，之后的分析：

1. 之前

代码报错的时候，线程执行未进入 try catch，那么无法捕捉异常。

比如语法异常（syntaxError），因为语法异常是在语法检查阶段就报错了，线程执行尚未进入 try catch 代码块，自然就无法捕获到异常。

2. 之中

代码报错的时候，线程执行处于 try catch 之中，则能捕捉到异常。

3. 之后

代码报错的时候，线程已经执行完 try catch，这种不能捕捉到异常。

总结：能被 try catch 捕捉到的异常，必须是在报错的时候，线程执行已经进入 try catch 代码块，且处在 try catch 里面，这个时候才能被捕捉到。

## Promise 没异常

Promise 的异常都是由 reject 和 Promise.prototype.catch 来捕获，不管是同步还是异步。

核心原因是因为 Promise 在执行回调中都用 try catch 包裹起来了，其中所有的异常都被内部捕获到了，并未往上抛异常。


